<?xml version="1.0" encoding="utf-8"?>
<!-- This URDF was automatically created by SolidWorks to URDF Exporter! Originally created by Stephen Brawner (brawner@gmail.com) 
     Commit Version: 1.6.0-4-g7f85cfe  Build Version: 1.6.7995.38578
     For more information, please see http://wiki.ros.org/sw_urdf_exporter -->
<robot xmlns:xacro="http://www.ros.org/wiki/xacro"  name="body">


  <link
    name="base_link">

  </link>

  <link name="chassis_link">
    <inertial>
      <origin
        xyz="0.014675 4.4183E-17 -0.040844"
        rpy="0 0 0" />
      <mass
        value="7" />
      <inertia
        ixx="0.44077"
        ixy="2.0222E-16"
        ixz="0.020835"
        iyy="0.57358"
        iyz="-7.1373E-17"
        izz="0.84637" />
    </inertial>
    <visual>
      <origin
        xyz="0 0 0"
        rpy="0 0 0" />
      <geometry>
        <mesh
          filename="file://$(find rover_description)/meshes/chassis_link.STL" />
      </geometry>
      <material
        name="">
        <color
          rgba="0.79216 0.81961 0.93333 1" />
      </material>
    </visual>
    <collision>
      <origin
        xyz="0 0 0"
        rpy="0 0 0" />
      <geometry>
        <mesh
          filename="file://$(find rover_description)/meshes/chassis_link.STL" />
      </geometry>
    </collision>
  </link>


  <gazebo reference="chassis_link">
        <material>Gazebo/White</material>
  </gazebo>

  <joint name="chassis_joint" type="fixed">
    <parent link="base_link" />
    <child link="chassis_link" />
    <origin xyz="0 0 0" />
  </joint>

  <link
    name="front_right_wheel_link">
    <inertial>
      <origin
        xyz="0.0146753114930385 4.4183075589603E-17 -0.0408444702966285"
        rpy="0 0 0" />
      <mass
        value="1" />
      <inertia
        ixx="0.440773403043026"
        ixy="2.0222253827549E-16"
        ixz="0.0208345815304579"
        iyy="0.57357932783604"
        iyz="-7.13726605678202E-17"
        izz="0.846373788852003" />
    </inertial>
    <visual>
      <origin
        xyz="0 0 0"
        rpy="0 0 0" />
      <geometry>
        <mesh
          filename="file://$(find rover_description)/meshes/front_right_wheel_link.STL" />
      </geometry>
      <material
        name="">
        <color
          rgba="0.298039215686275 0.298039215686275 0.298039215686275 1" />
      </material>
    </visual>
    <collision>
      <origin
        xyz="0 0 0"
        rpy="0 0 0" />
      <geometry>
        <mesh
          filename="file://$(find rover_description)/meshes/front_right_wheel_link.STL" />
      </geometry>
    </collision>
  </link>

  <gazebo reference="front_right_wheel_link">
        <material>Gazebo/Gray</material>
  </gazebo>


  <joint
    name="front_right_wheel_joint"
    type="continuous">
    <origin
      xyz="0.42117 -0.47112 -0.23635"
      rpy="0 0 0" />
    <parent
      link="base_link" />
    <child
      link="front_right_wheel_link" />
    <axis
      xyz="0 1 0" />
  </joint>

  
  <link
    name="rear_right_wheel_link">
    <inertial>
      <origin
        xyz="0.0146753114930385 4.4183075589603E-17 -0.0408444702966285"
        rpy="0 0 0" />
      <mass
        value="1" />
      <inertia
        ixx="0.440773403043026"
        ixy="2.0222253827549E-16"
        ixz="0.0208345815304579"
        iyy="0.57357932783604"
        iyz="-7.13726605678202E-17"
        izz="0.846373788852003" />
    </inertial>
    <visual>
      <origin
        xyz="0 0 0"
        rpy="0 0 0" />
      <geometry>
        <mesh
          filename="file://$(find rover_description)/meshes/rear_right_wheel_link.STL" />
      </geometry>
      <material
        name="">
        <color
          rgba="0.298039215686275 0.298039215686275 0.298039215686275 1" />
      </material>
    </visual>
    <collision>
      <origin
        xyz="0 0 0"
        rpy="0 0 0" />
      <geometry>
        <mesh
          filename="file://$(find rover_description)/meshes/rear_right_wheel_link.STL" />
      </geometry>
    </collision>
  </link>

  <gazebo reference="rear_right_wheel_link">
        <material>Gazebo/Gray</material>
  </gazebo>


  <joint
    name="rear_right_wheel_joint"
    type="continuous">
    <origin
      xyz="-0.25063 -0.47112 -0.23635"
      rpy="0 0 0" />
    <parent
      link="base_link" />
    <child
      link="rear_right_wheel_link" />
    <axis
      xyz="0 1 0" />
  </joint>
  <link
    name="front_left_wheel_link">
    <inertial>
      <origin
        xyz="0.0146753114930385 4.4183075589603E-17 -0.0408444702966285"
        rpy="0 0 0" />
      <mass
        value="1" />
      <inertia
        ixx="0.440773403043026"
        ixy="2.0222253827549E-16"
        ixz="0.0208345815304579"
        iyy="0.57357932783604"
        iyz="-7.13726605678202E-17"
        izz="0.846373788852003" />
    </inertial>
    <visual>
      <origin
        xyz="0 0 0"
        rpy="0 0 0" />
      <geometry>
        <mesh
          filename="file://$(find rover_description)/meshes/front_left_wheel_link.STL" />
      </geometry>
      <material
        name="">
        <color
          rgba="0.298039215686275 0.298039215686275 0.298039215686275 1" />
      </material>
    </visual>
    <collision>
      <origin
        xyz="0 0 0"
        rpy="0 0 0" />
      <geometry>
        <mesh
          filename="file://$(find rover_description)/meshes/front_left_wheel_link.STL" />
      </geometry>
    </collision>
  </link>

  <gazebo reference="front_left_wheel_link">
        <material>Gazebo/Gray</material>
  </gazebo>

  <joint
    name="front_left_wheel_joint"
    type="continuous">
    <origin
      xyz="0.42117 0.47112 -0.23635"
      rpy="0 0 0" />
    <parent
      link="base_link" />
    <child
      link="front_left_wheel_link" />
    <axis
      xyz="0 1 0" />
  </joint>
  <link
    name="rear_left_wheel_link">
    <inertial>
      <origin
        xyz="0.0146753114930385 4.4183075589603E-17 -0.0408444702966285"
        rpy="0 0 0" />
      <mass
        value="1" />
      <inertia
        ixx="0.440773403043026"
        ixy="2.0222253827549E-16"
        ixz="0.0208345815304579"
        iyy="0.57357932783604"
        iyz="-7.13726605678202E-17"
        izz="0.846373788852003" />
    </inertial>
    <visual>
      <origin
        xyz="0 0 0"
        rpy="0 0 0" />
      <geometry>
        <mesh
          filename="file://$(find rover_description)/meshes/rear_left_wheel_link.STL" />
      </geometry>
      <material
        name="">
        <color
          rgba="0.298039215686275 0.298039215686275 0.298039215686275 1" />
      </material>
    </visual>
    <collision>
      <origin
        xyz="0 0 0"
        rpy="0 0 0" />
      <geometry>
        <mesh
          filename="file://$(find rover_description)/meshes/rear_left_wheel_link.STL" />
      </geometry>
    </collision>
  </link>

  <gazebo reference="rear_left_wheel_link">
        <material>Gazebo/Gray</material>
  </gazebo>

  <joint
    name="rear_left_wheel_joint"
    type="continuous">
    <origin
      xyz="-0.25063 0.47112 -0.23635"
      rpy="0 0 0" />
    <parent
      link="base_link" />
    <child
      link="rear_left_wheel_link" />
    <axis
      xyz="0 1 0" />
  </joint>


  
</robot>